Workbook

Sheet Parameters & Summary
A1: Native App IAP Analysis — Partner Review
A2: Edit yellow cells to model different scenarios. All other tabs update automatically.
A4: ASSUMPTIONS (edit yellow cells)
A5: Parameter | B5: Value | C5: Notes
A6: Total users | B6: 10000 | C6: Overall user base
A7: Monthly subscribers | B7: 3000 | C7: Paying $4.99/mo
A8: Annual subscribers | B8: 2000 | C8: Paying $49.99/yr
A9: Scan pack buyers (annual) | B9: 3000 | C9: $1.99/10 scans
A11: Monthly sub price | B11: 4.99
A12: Annual sub price | B12: 49.99
A13: Scan pack price | B13: 1.99
A15: iOS share of premium users | B15: 0.5 | C15: % using iOS app
A16: Android share | B16: 0.4 | C16: % using Android app
A17: Web share | B17: 0.1 | C17: % web-only (always Stripe)
A19: Apple fee rate (SBP) | B19: 0.15 | C19: 15% under $1M/yr dev revenue; 30% standard
A20: Google Play fee (SBP) | B20: 0.15 | C20: 15% under $1M/yr
A21: Stripe percent fee | B21: 0.029 | C21: 2.9% per transaction
A22: Stripe flat fee per txn | B22: 0.3
A24: Opt C: iOS→web conversion | B24: 0.6 | C24: % of iOS users who'd pay who follow through when forced to web
A25: Opt D: iOS→web conversion | B25: 0.2 | C25: % of iOS users who give up premium vs switching to web
A28: CHANNEL GROSS REVENUE (derived)
A29: Channel | B29: Share | C29: Monthly subs gross | D29: Annual subs gross | E29: Scan packs gross | F29: Total gross
A30: iOS | B30: ='Parameters & Summary'!$B$15 | C30: ='Parameters & Summary'!$B$15*'Parameters & Summary'!$B$7*'Parameters & Summary'!$B$11*12 | D30: ='Parameters & Summary'!$B$15*'Parameters & Summary'!$B$8*'Parameters & Summary'!$B$12 | E30: ='Parameters & Summary'!$B$15*'Parameters & Summary'!$B$9*'Parameters & Summary'!$B$13 | F30: =SUM(C30:E30)
A31: Android | B31: ='Parameters & Summary'!$B$16 | C31: ='Parameters & Summary'!$B$16*'Parameters & Summary'!$B$7*'Parameters & Summary'!$B$11*12 | D31: ='Parameters & Summary'!$B$16*'Parameters & Summary'!$B$8*'Parameters & Summary'!$B$12 | E31: ='Parameters & Summary'!$B$16*'Parameters & Summary'!$B$9*'Parameters & Summary'!$B$13 | F31: =SUM(C31:E31)
A32: Web | B32: ='Parameters & Summary'!$B$17 | C32: ='Parameters & Summary'!$B$17*'Parameters & Summary'!$B$7*'Parameters & Summary'!$B$11*12 | D32: ='Parameters & Summary'!$B$17*'Parameters & Summary'!$B$8*'Parameters & Summary'!$B$12 | E32: ='Parameters & Summary'!$B$17*'Parameters & Summary'!$B$9*'Parameters & Summary'!$B$13 | F32: =SUM(C32:E32)
A33: Total | B33: =SUM(B30:B32) | C33: =SUM(C30:C32) | D33: =SUM(D30:D32) | E33: =SUM(E30:E32) | F33: =SUM(F30:F32)
A35: STRIPE FEES PER CHANNEL (if channel is on Stripe)
A36: Channel | B36: Stripe fees
A37: iOS | B37: =('Parameters & Summary'!$B$15*'Parameters & Summary'!$B$7*12*('Parameters & Summary'!$B$11*'Parameters & Summary'!$B$21+'Parameters & Summary'!$B$22))+('Parameters & Summary'!$B$15*'Parameters & Summary'!$B$8*('Parameters & Summary'!$B$12*'Parameters & Summary'!$B$21+'Parameters & Summary'!$B$22))+('Parameters & Summary'!$B$15*'Parameters & Summary'!$B$9*('Parameters & Summary'!$B$13*'Parameters & Summary'!$B$21+'Parameters & Summary'!$B$22))
A38: Android | B38: =('Parameters & Summary'!$B$16*'Parameters & Summary'!$B$7*12*('Parameters & Summary'!$B$11*'Parameters & Summary'!$B$21+'Parameters & Summary'!$B$22))+('Parameters & Summary'!$B$16*'Parameters & Summary'!$B$8*('Parameters & Summary'!$B$12*'Parameters & Summary'!$B$21+'Parameters & Summary'!$B$22))+('Parameters & Summary'!$B$16*'Parameters & Summary'!$B$9*('Parameters & Summary'!$B$13*'Parameters & Summary'!$B$21+'Parameters & Summary'!$B$22))
A39: Web | B39: =('Parameters & Summary'!$B$17*'Parameters & Summary'!$B$7*12*('Parameters & Summary'!$B$11*'Parameters & Summary'!$B$21+'Parameters & Summary'!$B$22))+('Parameters & Summary'!$B$17*'Parameters & Summary'!$B$8*('Parameters & Summary'!$B$12*'Parameters & Summary'!$B$21+'Parameters & Summary'!$B$22))+('Parameters & Summary'!$B$17*'Parameters & Summary'!$B$9*('Parameters & Summary'!$B$13*'Parameters & Summary'!$B$21+'Parameters & Summary'!$B$22))
A42: SIDE-BY-SIDE STRATEGY COMPARISON
A43: Strategy | B43: Apple fee | C43: Google fee | D43: Stripe fees | E43: Total fees | F43: Net revenue | G43: vs Baseline | H43: % hit to net
A44: Baseline (all Stripe, web only) | B44: 0 | C44: 0 | D44: ='Parameters & Summary'!$B$37+'Parameters & Summary'!$B$38+'Parameters & Summary'!$B$39 | E44: =B44+C44+D44 | F44: ='Parameters & Summary'!$F$33-E44 | G44: =F44-$F$44 | H44: =(F44-$F$44)/$F$44
A45: A — Apple IAP + Stripe (Android+Web) | B45: ='Parameters & Summary'!$F$30*'Parameters & Summary'!$B$19 | C45: 0 | D45: ='Parameters & Summary'!$B$38+'Parameters & Summary'!$B$39 | E45: =B45+C45+D45 | F45: ='Parameters & Summary'!$F$33-E45 | G45: =F45-$F$44 | H45: =(F45-$F$44)/$F$44
A46: B — Apple IAP + Google Play (Web on Stripe) | B46: ='Parameters & Summary'!$F$30*'Parameters & Summary'!$B$19 | C46: ='Parameters & Summary'!$F$31*'Parameters & Summary'!$B$20 | D46: ='Parameters & Summary'!$B$39 | E46: =B46+C46+D46 | F46: ='Parameters & Summary'!$F$33-E46 | G46: =F46-$F$44 | H46: =(F46-$F$44)/$F$44
A47: C — Web-only iOS upgrades | B47: 0 | C47: 0 | D47: =('Parameters & Summary'!$B$37*'Parameters & Summary'!$B$24)+'Parameters & Summary'!$B$38+'Parameters & Summary'!$B$39 | E47: =B47+C47+D47 | F47: =('Parameters & Summary'!$F$30*'Parameters & Summary'!$B$24)+'Parameters & Summary'!$F$31+'Parameters & Summary'!$F$32-E47 | G47: =F47-$F$44 | H47: =(F47-$F$44)/$F$44
A48: D — iOS free-only (no iOS upgrades) | B48: 0 | C48: 0 | D48: =('Parameters & Summary'!$B$37*'Parameters & Summary'!$B$25)+'Parameters & Summary'!$B$38+'Parameters & Summary'!$B$39 | E48: =B48+C48+D48 | F48: =('Parameters & Summary'!$F$30*'Parameters & Summary'!$B$25)+'Parameters & Summary'!$F$31+'Parameters & Summary'!$F$32-E48 | G48: =F48-$F$44 | H48: =(F48-$F$44)/$F$44
A51: KEY TAKEAWAYS
A52: 1. Apple's auction marketplace is unaffected — physical goods are exempt from IAP. Only Premium + scan packs trigger Apple/Google fees.
...

Sheet Baseline (all Stripe)
A1: Baseline (all Stripe)
A2: Current state — web-only, all payments via Stripe. No native apps. No Apple/Google fees. Reference point for all other scenarios.
A4: KEY PARAMETERS (linked from Parameters tab)
A5: Monthly subs | B5: ='Parameters & Summary'!$B$7
A6: Annual subs | B6: ='Parameters & Summary'!$B$8
A7: Scan pack buyers/yr | B7: ='Parameters & Summary'!$B$9
A8: iOS share | B8: ='Parameters & Summary'!$B$15
A9: Android share | B9: ='Parameters & Summary'!$B$16
A10: Web share | B10: ='Parameters & Summary'!$B$17
A11: Apple fee (SBP) | B11: ='Parameters & Summary'!$B$19
A12: Google fee (SBP) | B12: ='Parameters & Summary'!$B$20
A15: PER-CHANNEL BREAKDOWN
A16: Channel | B16: Gross | C16: Apple fee | D16: Google fee | E16: Stripe fee | F16: Net
A17: iOS (web) | B17: ='Parameters & Summary'!$F$30 | C17: 0 | D17: 0 | E17: ='Parameters & Summary'!$B$37 | F17: =B17-C17-D17-E17
A18: Android (web) | B18: ='Parameters & Summary'!$F$31 | C18: 0 | D18: 0 | E18: ='Parameters & Summary'!$B$38 | F18: =B18-C18-D18-E18
A19: Web | B19: ='Parameters & Summary'!$F$32 | C19: 0 | D19: 0 | E19: ='Parameters & Summary'!$B$39 | F19: =B19-C19-D19-E19
A20: Total | B20: =SUM(B17:B19) | C20: =SUM(C17:C19) | D20: =SUM(D17:D19) | E20: =SUM(E17:E19) | F20: =SUM(F17:F19)
A22: Net vs Baseline | B22: =F20-'Parameters & Summary'!$F$44 | C22: % of baseline net | D22: =(F20-'Parameters & Summary'!$F$44)/'Parameters & Summary'!$F$44

Sheet Option A - Apple IAP + Stripe
A1: Option A - Apple IAP + Stripe
A2: Ship iOS with Apple IAP for Premium + scan packs. Android + Web continue using Stripe (assumes Google Play User Choice Billing). Preserves full iOS revenue minus Apple's 15% SBP cut.
A4: KEY PARAMETERS (linked from Parameters tab)
A5: Monthly subs | B5: ='Parameters & Summary'!$B$7
A6: Annual subs | B6: ='Parameters & Summary'!$B$8
A7: Scan pack buyers/yr | B7: ='Parameters & Summary'!$B$9
A8: iOS share | B8: ='Parameters & Summary'!$B$15
A9: Android share | B9: ='Parameters & Summary'!$B$16
A10: Web share | B10: ='Parameters & Summary'!$B$17
A11: Apple fee (SBP) | B11: ='Parameters & Summary'!$B$19
A12: Google fee (SBP) | B12: ='Parameters & Summary'!$B$20
A15: PER-CHANNEL BREAKDOWN
A16: Channel | B16: Gross | C16: Apple fee | D16: Google fee | E16: Stripe fee | F16: Net
A17: iOS (Apple IAP) | B17: ='Parameters & Summary'!$F$30 | C17: ='Parameters & Summary'!$F$30*'Parameters & Summary'!$B$19 | D17: 0 | E17: 0 | F17: =B17-C17-D17-E17
A18: Android (Stripe) | B18: ='Parameters & Summary'!$F$31 | C18: 0 | D18: 0 | E18: ='Parameters & Summary'!$B$38 | F18: =B18-C18-D18-E18
A19: Web (Stripe) | B19: ='Parameters & Summary'!$F$32 | C19: 0 | D19: 0 | E19: ='Parameters & Summary'!$B$39 | F19: =B19-C19-D19-E19
A20: Total | B20: =SUM(B17:B19) | C20: =SUM(C17:C19) | D20: =SUM(D17:D19) | E20: =SUM(E17:E19) | F20: =SUM(F17:F19)
A22: Net vs Baseline | B22: =F20-'Parameters & Summary'!$F$44 | C22: % of baseline net | D22: =(F20-'Parameters & Summary'!$F$44)/'Parameters & Summary'!$F$44

Sheet Option B - Both store billing
A1: Option B - Both store billing
A2: Ship iOS with Apple IAP AND Android with Google Play Billing. Web stays on Stripe. Safest / most compliant, but both stores take a cut of digital subs and consumables.
A4: KEY PARAMETERS (linked from Parameters tab)
A5: Monthly subs | B5: ='Parameters & Summary'!$B$7
A6: Annual subs | B6: ='Parameters & Summary'!$B$8
A7: Scan pack buyers/yr | B7: ='Parameters & Summary'!$B$9
A8: iOS share | B8: ='Parameters & Summary'!$B$15
A9: Android share | B9: ='Parameters & Summary'!$B$16
A10: Web share | B10: ='Parameters & Summary'!$B$17
A11: Apple fee (SBP) | B11: ='Parameters & Summary'!$B$19
A12: Google fee (SBP) | B12: ='Parameters & Summary'!$B$20
A15: PER-CHANNEL BREAKDOWN
A16: Channel | B16: Gross | C16: Apple fee | D16: Google fee | E16: Stripe fee | F16: Net
A17: iOS (Apple IAP) | B17: ='Parameters & Summary'!$F$30 | C17: ='Parameters & Summary'!$F$30*'Parameters & Summary'!$B$19 | D17: 0 | E17: 0 | F17: =B17-C17-D17-E17
A18: Android (Google Play) | B18: ='Parameters & Summary'!$F$31 | C18: 0 | D18: ='Parameters & Summary'!$F$31*'Parameters & Summary'!$B$20 | E18: 0 | F18: =B18-C18-D18-E18
A19: Web (Stripe) | B19: ='Parameters & Summary'!$F$32 | C19: 0 | D19: 0 | E19: ='Parameters & Summary'!$B$39 | F19: =B19-C19-D19-E19
A20: Total | B20: =SUM(B17:B19) | C20: =SUM(C17:C19) | D20: =SUM(D17:D19) | E20: =SUM(E17:E19) | F20: =SUM(F17:F19)
A22: Net vs Baseline | B22: =F20-'Parameters & Summary'!$F$44 | C22: % of baseline net | D22: =(F20-'Parameters & Summary'!$F$44)/'Parameters & Summary'!$F$44

Sheet Option C - Web-only upgrades
A1: Option C - Web-only upgrades
A2: iOS app has NO in-app purchase path. Users must sign up / upgrade on the website. Apple's anti-steering rules prohibit linking out. Avoids IAP fees but loses revenue to conversion drop (industry typical ~40% drop).
A4: KEY PARAMETERS (linked from Parameters tab)
A5: Monthly subs | B5: ='Parameters & Summary'!$B$7
A6: Annual subs | B6: ='Parameters & Summary'!$B$8
A7: Scan pack buyers/yr | B7: ='Parameters & Summary'!$B$9
A8: iOS share | B8: ='Parameters & Summary'!$B$15
A9: Android share | B9: ='Parameters & Summary'!$B$16
A10: Web share | B10: ='Parameters & Summary'!$B$17
A11: Apple fee (SBP) | B11: ='Parameters & Summary'!$B$19
A12: Google fee (SBP) | B12: ='Parameters & Summary'!$B$20
A13: Opt C conversion rate | B13: ='Parameters & Summary'!$B$24
A16: PER-CHANNEL BREAKDOWN
A17: Channel | B17: Gross | C17: Apple fee | D17: Google fee | E17: Stripe fee | F17: Net
A18: iOS (web, partial capture) | B18: ='Parameters & Summary'!$F$30*'Parameters & Summary'!$B$24 | C18: 0 | D18: 0 | E18: ='Parameters & Summary'!$B$37*'Parameters & Summary'!$B$24 | F18: =B18-C18-D18-E18
A19: Android (Stripe) | B19: ='Parameters & Summary'!$F$31 | C19: 0 | D19: 0 | E19: ='Parameters & Summary'!$B$38 | F19: =B19-C19-D19-E19
A20: Web (Stripe) | B20: ='Parameters & Summary'!$F$32 | C20: 0 | D20: 0 | E20: ='Parameters & Summary'!$B$39 | F20: =B20-C20-D20-E20
A21: Total | B21: =SUM(B18:B20) | C21: =SUM(C18:C20) | D21: =SUM(D18:D20) | E21: =SUM(E18:E20) | F21: =SUM(F18:F20)
A23: Net vs Baseline | B23: =F21-'Parameters & Summary'!$F$44 | C23: % of baseline net | D23: =(F21-'Parameters & Summary'!$F$44)/'Parameters & Summary'!$F$44

Sheet Option D - iOS free-only
A1: Option D - iOS free-only
A2: iOS app has no upgrade path at all. Only free-tier features available on iOS. Users who want Premium must use web/Android. Lowest App Store rejection risk but caps iOS revenue severely.
A4: KEY PARAMETERS (linked from Parameters tab)
A5: Monthly subs | B5: ='Parameters & Summary'!$B$7
A6: Annual subs | B6: ='Parameters & Summary'!$B$8
A7: Scan pack buyers/yr | B7: ='Parameters & Summary'!$B$9
A8: iOS share | B8: ='Parameters & Summary'!$B$15
A9: Android share | B9: ='Parameters & Summary'!$B$16
A10: Web share | B10: ='Parameters & Summary'!$B$17
A11: Apple fee (SBP) | B11: ='Parameters & Summary'!$B$19
A12: Google fee (SBP) | B12: ='Parameters & Summary'!$B$20
A13: Opt D conversion rate | B13: ='Parameters & Summary'!$B$25
A16: PER-CHANNEL BREAKDOWN
A17: Channel | B17: Gross | C17: Apple fee | D17: Google fee | E17: Stripe fee | F17: Net
A18: iOS (few go to web) | B18: ='Parameters & Summary'!$F$30*'Parameters & Summary'!$B$25 | C18: 0 | D18: 0 | E18: ='Parameters & Summary'!$B$37*'Parameters & Summary'!$B$25 | F18: =B18-C18-D18-E18
A19: Android (Stripe) | B19: ='Parameters & Summary'!$F$31 | C19: 0 | D19: 0 | E19: ='Parameters & Summary'!$B$38 | F19: =B19-C19-D19-E19
A20: Web (Stripe) | B20: ='Parameters & Summary'!$F$32 | C20: 0 | D20: 0 | E20: ='Parameters & Summary'!$B$39 | F20: =B20-C20-D20-E20
A21: Total | B21: =SUM(B18:B20) | C21: =SUM(C18:C20) | D21: =SUM(D18:D20) | E21: =SUM(E18:E20) | F21: =SUM(F18:F20)
A23: Net vs Baseline | B23: =F21-'Parameters & Summary'!$F$44 | C23: % of baseline net | D23: =(F21-'Parameters & Summary'!$F$44)/'Parameters & Summary'!$F$44

Sheet Growth Sensitivity
A1: Growth Sensitivity — When Does Native Pay Off?
A2: Assumption: PWA-only revenue is capped at current user count (App Store is a growth channel the PWA doesn't tap). Native apps scale linearly with users if premium conversion % stays constant. Break-even: how much user growth native must bring to match PWA-only net.
A4: BREAK-EVEN ANALYSIS
A5: Strategy | B5: Net at 1x users | C5: Break-even multiplier | D5: Extra users needed | E5: Interpretation
A6: Option A (Apple IAP + Stripe) | B6: ='Parameters & Summary'!$F$45 | C6: ='Parameters & Summary'!$F$44/'Parameters & Summary'!$F$45 | D6: =('Parameters & Summary'!$F$44/'Parameters & Summary'!$F$45-1)*'Parameters & Summary'!$B$7/0.3 | E6: Extra users the App Store must bring just to offset Apple's cut
A7: Option B (Apple IAP + Google Play) | B7: ='Parameters & Summary'!$F$46 | C7: ='Parameters & Summary'!$F$44/'Parameters & Summary'!$F$46 | D7: =('Parameters & Summary'!$F$44/'Parameters & Summary'!$F$46-1)*'Parameters & Summary'!$B$7/0.3 | E7: Extra users both stores' cuts must be offset by
A10: NET REVENUE AT DIFFERENT GROWTH MULTIPLIERS
A11: User multiplier | B11: Total users | C11: Total premium | D11: PWA-only net | E11: Option A net | F11: Option B net | G11: A vs PWA | H11: B vs PWA
A12: 1 | B12: =('Parameters & Summary'!$B$7+'Parameters & Summary'!$B$8)*(1/(('Parameters & Summary'!$B$7+'Parameters & Summary'!$B$8)/'Parameters & Summary'!$B$6))*A12 | C12: =('Parameters & Summary'!$B$7+'Parameters & Summary'!$B$8+'Parameters & Summary'!$B$9)*A12 | D12: ='Parameters & Summary'!$F$44 | E12: ='Parameters & Summary'!$F$45*A12 | F12: ='Parameters & Summary'!$F$46*A12 | G12: =E12-D12 | H12: =F12-D12
A13: 1.1 | B13: =('Parameters & Summary'!$B$7+'Parameters & Summary'!$B$8)*(1/(('Parameters & Summary'!$B$7+'Parameters & Summary'!$B$8)/'Parameters & Summary'!$B$6))*A13 | C13: =('Parameters & Summary'!$B$7+'Parameters & Summary'!$B$8+'Parameters & Summary'!$B$9)*A13 | D13: ='Parameters & Summary'!$F$44 | E13: ='Parameters & Summary'!$F$45*A13 | F13: ='Parameters & Summary'!$F$46*A13 | G13: =E13-D13 | H13: =F13-D13
A14: 1.25 | B14: =('Parameters & Summary'!$B$7+'Parameters & Summary'!$B$8)*(1/(('Parameters & Summary'!$B$7+'Parameters & Summary'!$B$8)/'Parameters & Summary'!$B$6))*A14 | C14: =('Parameters & Summary'!$B$7+'Parameters & Summary'!$B$8+'Parameters & Summary'!$B$9)*A14 | D14: ='Parameters & Summary'!$F$44 | E14: ='Parameters & Summary'!$F$45*A14 | F14: ='Parameters & Summary'!$F$46*A14 | G14: =E14-D14 | H14: =F14-D14
A15: 1.5 | B15: =('Parameters & Summary'!$B$7+'Parameters & Summary'!$B$8)*(1/(('Parameters & Summary'!$B$7+'Parameters & Summary'!$B$8)/'Parameters & Summary'!$B$6))*A15 | C15: =('Parameters & Summary'!$B$7+'Parameters & Summary'!$B$8+'Parameters & Summary'!$B$9)*A15 | D15: ='Parameters & Summary'!$F$44 | E15: ='Parameters & Summary'!$F$45*A15 | F15: ='Parameters & Summary'!$F$46*A15 | G15: =E15-D15 | H15: =F15-D15
A16: 1.75 | B16: =('Parameters & Summary'!$B$7+'Parameters & Summary'!$B$8)*(1/(('Parameters & Summary'!$B$7+'Parameters & Summary'!$B$8)/'Parameters & Summary'!$B$6))*A16 | C16: =('Parameters & Summary'!$B$7+'Parameters & Summary'!$B$8+'Parameters & Summary'!$B$9)*A16 | D16: ='Parameters & Summary'!$F$44 | E16: ='Parameters & Summary'!$F$45*A16 | F16: ='Parameters & Summary'!$F$46*A16 | G16: =E16-D16 | H16: =F16-D16
A17: 2 | B17: =('Parameters & Summary'!$B$7+'Parameters & Summary'!$B$8)*(1/(('Parameters & Summary'!$B$7+'Parameters & Summary'!$B$8)/'Parameters & Summary'!$B$6))*A17 | C17: =('Parameters & Summary'!$B$7+'Parameters & Summary'!$B$8+'Parameters & Summary'!$B$9)*A17 | D17: ='Parameters & Summary'!$F$44 | E17: ='Parameters & Summary'!$F$45*A17 | F17: ='Parameters & Summary'!$F$46*A17 | G17: =E17-D17 | H17: =F17-D17
A18: 2.5 | B18: =('Parameters & Summary'!$B$7+'Parameters & Summary'!$B$8)*(1/(('Parameters & Summary'!$B$7+'Parameters & Summary'!$B$8)/'Parameters & Summary'!$B$6))*A18 | C18: =('Parameters & Summary'!$B$7+'Parameters & Summary'!$B$8+'Parameters & Summary'!$B$9)*A18 | D18: ='Parameters & Summary'!$F$44 | E18: ='Parameters & Summary'!$F$45*A18 | F18: ='Parameters & Summary'!$F$46*A18 | G18: =E18-D18 | H18: =F18-D18
A19: 3 | B19: =('Parameters & Summary'!$B$7+'Parameters & Summary'!$B$8)*(1/(('Parameters & Summary'!$B$7+'Parameters & Summary'!$B$8)/'Parameters & Summary'!$B$6))*A19 | C19: =('Parameters & Summary'!$B$7+'Parameters & Summary'!$B$8+'Parameters & Summary'!$B$9)*A19 | D19: ='Parameters & Summary'!$F$44 | E19: ='Parameters & Summary'!$F$45*A19 | F19: ='Parameters & Summary'!$F$46*A19 | G19: =E19-D19 | H19: =F19-D19
A20: 4 | B20: =('Parameters & Summary'!$B$7+'Parameters & Summary'!$B$8)*(1/(('Parameters & Summary'!$B$7+'Parameters & Summary'!$B$8)/'Parameters & Summary'!$B$6))*A20 | C20: =('Parameters & Summary'!$B$7+'Parameters & Summary'!$B$8+'Parameters & Summary'!$B$9)*A20 | D20: ='Parameters & Summary'!$F$44 | E20: ='Parameters & Summary'!$F$45*A20 | F20: ='Parameters & Summary'!$F$46*A20 | G20: =E20-D20 | H20: =F20-D20
A21: 5 | B21: =('Parameters & Summary'!$B$7+'Parameters & Summary'!$B$8)*(1/(('Parameters & Summary'!$B$7+'Parameters & Summary'!$B$8)/'Parameters & Summary'!$B$6))*A21 | C21: =('Parameters & Summary'!$B$7+'Parameters & Summary'!$B$8+'Parameters & Summary'!$B$9)*A21 | D21: ='Parameters & Summary'!$F$44 | E21: ='Parameters & Summary'!$F$45*A21 | F21: ='Parameters & Summary'!$F$46*A21 | G21: =E21-D21 | H21: =F21-D21
A24: HOW TO READ THIS
A25: • PWA-only assumes the user base is capped at its current level. If word-of-mouth growth can double the PWA base too, this analysis understates PWA-only revenue.
A26: • Option A/B nets scale linearly with users, assuming premium conversion % (~50%) and platform split (50/40/10) stay constant.
A27: • Break-even shows the minimum user-base multiplier the App Store must deliver to match PWA-only net. Anything above break-even = native wins.
A28: • Typical rule of thumb: adding App Store + Play Store distribution grows consumer app user base 1.5x–3x over pure PWA/web (highly dependent on category and marketing).
A29: • Comics/collectibles apps tend toward the higher end of that range because app-store browsing is a common discovery path for niche-hobby apps.
A30: • If you expect <1.1x growth from native apps, Option A is essentially a wash — fees eat the incremental users. Above 1.5x, native clearly wins.
A31: • Alternative play: stay PWA-only for v1, add native apps once organic traction is proven and you can afford the IAP engineering upfront.
